Workbook

Sheet Record
G1: ใส่เงินลงทุนเริ่มต้น >>>>>>>> | K1: 15000 | M1: Play 4H
A2: Open | F2: Close | I2: Gain | K2: Loss | M2: Feedback | O2: Score Board
A3: Date | B3: Order | C3: Side | D3: Price | E3: Volume | F3: Price | I3: จุด | J3: Amount | K3: จุด | L3: Amount | O3: Accuracy & Gain/Loss perform
A4: 17/3/2026 | B4: 1 | C4: L | D4: 929 | E4: 1 | F4: 944.5 | I4: =IF(C4="L",IF(F4-D4>0,F4-D4," "),IF(D4-F4>0,D4-F4," ")) -> 15.5 | J4: =IF(C4="L",IF(F4-D4>0,(F4-D4)*200*E4," "),IF(D4-F4>0,(D4-F4)*200*E4," ")) -> 3100 | K4: =IF(C4="L",IF(F4-D4<0,F4-D4," "),IF(D4-F4<0,D4-F4," ")) | L4: =IF(C4="L",IF(F4-D4<0,(F4-D4)*200*E4," "),IF(D4-F4<0,(D4-F4)*200*E4," ")) | N4: M | O4: Total Trade | P4: =B29+C29 -> 1
B5: 2 | I5: =IF(C5="L",IF(F5-D5>0,F5-D5," "),IF(D5-F5>0,D5-F5," ")) | J5: =IF(C5="L",IF(F5-D5>0,(F5-D5)*200*E5," "),IF(D5-F5>0,(D5-F5)*200*E5," ")) | K5: =IF(C5="L",IF(F5-D5<0,F5-D5," "),IF(D5-F5<0,D5-F5," ")) | L5: =IF(C5="L",IF(F5-D5<0,(F5-D5)*200*E5," "),IF(D5-F5<0,(D5-F5)*200*E5," ")) | O5: Winning Chance | P5: =B29/P4*100 -> 100 | Q5: Loss Chance | R5: =C29/P4*100 -> 0
B6: 3 | I6: =IF(C6="L",IF(F6-D6>0,F6-D6," "),IF(D6-F6>0,D6-F6," ")) | J6: =IF(C6="L",IF(F6-D6>0,(F6-D6)*200*E6," "),IF(D6-F6>0,(D6-F6)*200*E6," ")) | K6: =IF(C6="L",IF(F6-D6<0,F6-D6," "),IF(D6-F6<0,D6-F6," ")) | L6: =IF(C6="L",IF(F6-D6<0,(F6-D6)*200*E6," "),IF(D6-F6<0,(D6-F6)*200*E6," ")) | O6: Average Gain | P6: =SUM(I5:I28)/B29 -> 0 | Q6: Average Loss | R6: =SUM(K5:K28)/C29 -> #DIV/0!
B7: 4 | I7: =IF(C7="L",IF(F7-D7>0,F7-D7," "),IF(D7-F7>0,D7-F7," ")) | J7: =IF(C7="L",IF(F7-D7>0,(F7-D7)*200*E7," "),IF(D7-F7>0,(D7-F7)*200*E7," ")) | K7: =IF(C7="L",IF(F7-D7<0,F7-D7," "),IF(D7-F7<0,D7-F7," ")) | L7: =IF(C7="L",IF(F7-D7<0,(F7-D7)*200*E7," "),IF(D7-F7<0,(D7-F7)*200*E7," ")) | O7: Total Gain | P7: =SUM(J4:J28) -> 3100 | Q7: Total Loss | R7: =SUM(L4:L28) -> 0
B8: 5 | I8: =IF(C8="L",IF(F8-D8>0,F8-D8," "),IF(D8-F8>0,D8-F8," ")) | J8: =IF(C8="L",IF(F8-D8>0,(F8-D8)*200*E8," "),IF(D8-F8>0,(D8-F8)*200*E8," ")) | K8: =IF(C8="L",IF(F8-D8<0,F8-D8," "),IF(D8-F8<0,D8-F8," ")) | L8: =IF(C8="L",IF(F8-D8<0,(F8-D8)*200*E8," "),IF(D8-F8<0,(D8-F8)*200*E8," ")) | O8: Performance
B9: 6 | I9: =IF(C9="L",IF(F9-D9>0,F9-D9," "),IF(D9-F9>0,D9-F9," ")) | J9: =IF(C9="L",IF(F9-D9>0,(F9-D9)*200*E9," "),IF(D9-F9>0,(D9-F9)*200*E9," ")) | K9: =IF(C9="L",IF(F9-D9<0,F9-D9," "),IF(D9-F9<0,D9-F9," ")) | L9: =IF(C9="L",IF(F9-D9<0,(F9-D9)*200*E9," "),IF(D9-F9<0,(D9-F9)*200*E9," ")) | O9: Net Profit | P9: =P7+R7-K30 -> 3067.9 | Q9: Cost rate | R9: =K30/P9 -> 0.010463183
B10: 7 | I10: =IF(C10="L",IF(F10-D10>0,F10-D10," "),IF(D10-F10>0,D10-F10," ")) | J10: =IF(C10="L",IF(F10-D10>0,(F10-D10)*200*E10," "),IF(D10-F10>0,(D10-F10)*200*E10," ")) | K10: =IF(C10="L",IF(F10-D10<0,F10-D10," "),IF(D10-F10<0,D10-F10," ")) | L10: =IF(C10="L",IF(F10-D10<0,(F10-D10)*200*E10," "),IF(D10-F10<0,(D10-F10)*200*E10," "))
B11: 8 | I11: =IF(C11="L",IF(F11-D11>0,F11-D11," "),IF(D11-F11>0,D11-F11," ")) | J11: =IF(C11="L",IF(F11-D11>0,(F11-D11)*200*E11," "),IF(D11-F11>0,(D11-F11)*200*E11," ")) | K11: =IF(C11="L",IF(F11-D11<0,F11-D11," "),IF(D11-F11<0,D11-F11," ")) | L11: =IF(C11="L",IF(F11-D11<0,(F11-D11)*200*E11," "),IF(D11-F11<0,(D11-F11)*200*E11," ")) | O11: Expected Return | R11: =IF(R7<0,((P5*P6/100)+(R5*R6/100)),P6) -> 0
B12: 9 | I12: =IF(C12="L",IF(F12-D12>0,F12-D12," "),IF(D12-F12>0,D12-F12," ")) | J12: =IF(C12="L",IF(F12-D12>0,(F12-D12)*200*E12," "),IF(D12-F12>0,(D12-F12)*200*E12," ")) | K12: =IF(C12="L",IF(F12-D12<0,F12-D12," "),IF(D12-F12<0,D12-F12," ")) | L12: =IF(C12="L",IF(F12-D12<0,(F12-D12)*200*E12," "),IF(D12-F12<0,(D12-F12)*200*E12," "))
B13: 10 | I13: =IF(C13="L",IF(F13-D13>0,F13-D13," "),IF(D13-F13>0,D13-F13," ")) | J13: =IF(C13="L",IF(F13-D13>0,(F13-D13)*200*E13," "),IF(D13-F13>0,(D13-F13)*200*E13," ")) | K13: =IF(C13="L",IF(F13-D13<0,F13-D13," "),IF(D13-F13<0,D13-F13," ")) | L13: =IF(C13="L",IF(F13-D13<0,(F13-D13)*200*E13," "),IF(D13-F13<0,(D13-F13)*200*E13," "))
B14: 11 | I14: =IF(C14="L",IF(F14-D14>0,F14-D14," "),IF(D14-F14>0,D14-F14," ")) | J14: =IF(C14="L",IF(F14-D14>0,(F14-D14)*200*E14," "),IF(D14-F14>0,(D14-F14)*200*E14," ")) | K14: =IF(C14="L",IF(F14-D14<0,F14-D14," "),IF(D14-F14<0,D14-F14," ")) | L14: =IF(C14="L",IF(F14-D14<0,(F14-D14)*200*E14," "),IF(D14-F14<0,(D14-F14)*200*E14," ")) | O14: Top Ranking
B15: 12 | I15: =IF(C15="L",IF(F15-D15>0,F15-D15," "),IF(D15-F15>0,D15-F15," ")) | J15: =IF(C15="L",IF(F15-D15>0,(F15-D15)*200*E15," "),IF(D15-F15>0,(D15-F15)*200*E15," ")) | K15: =IF(C15="L",IF(F15-D15<0,F15-D15," "),IF(D15-F15<0,D15-F15," ")) | L15: =IF(C15="L",IF(F15-D15<0,(F15-D15)*200*E15," "),IF(D15-F15<0,(D15-F15)*200*E15," ")) | O15: Best Gain | P15: =MAX(I5:I28) -> 0 | R15: =P15-P17 -> 0
B16: 13 | I16: =IF(C16="L",IF(F16-D16>0,F16-D16," "),IF(D16-F16>0,D16-F16," ")) | J16: =IF(C16="L",IF(F16-D16>0,(F16-D16)*200*E16," "),IF(D16-F16>0,(D16-F16)*200*E16," ")) | K16: =IF(C16="L",IF(F16-D16<0,F16-D16," "),IF(D16-F16<0,D16-F16," ")) | L16: =IF(C16="L",IF(F16-D16<0,(F16-D16)*200*E16," "),IF(D16-F16<0,(D16-F16)*200*E16," ")) | O16: Best Gain Amount | P16: =MAX(J4:J28) -> 3100
B17: 14 | I17: =IF(C17="L",IF(F17-D17>0,F17-D17," "),IF(D17-F17>0,D17-F17," ")) | J17: =IF(C17="L",IF(F17-D17>0,(F17-D17)*200*E17," "),IF(D17-F17>0,(D17-F17)*200*E17," ")) | K17: =IF(C17="L",IF(F17-D17<0,F17-D17," "),IF(D17-F17<0,D17-F17," ")) | L17: =IF(C17="L",IF(F17-D17<0,(F17-D17)*200*E17," "),IF(D17-F17<0,(D17-F17)*200*E17," ")) | O17: Bad Loss | P17: =MIN(K5:K28) -> 0
B18: 15 | I18: =IF(C18="L",IF(F18-D18>0,F18-D18," "),IF(D18-F18>0,D18-F18," ")) | J18: =IF(C18="L",IF(F18-D18>0,(F18-D18)*200*E18," "),IF(D18-F18>0,(D18-F18)*200*E18," ")) | K18: =IF(C18="L",IF(F18-D18<0,F18-D18," "),IF(D18-F18<0,D18-F18," ")) | L18: =IF(C18="L",IF(F18-D18<0,(F18-D18)*200*E18," "),IF(D18-F18<0,(D18-F18)*200*E18," ")) | O18: Bad Loss Amount | P18: =MIN(L4:L28) -> 0
B19: 16 | I19: =IF(C19="L",IF(F19-D19>0,F19-D19," "),IF(D19-F19>0,D19-F19," ")) | J19: =IF(C19="L",IF(F19-D19>0,(F19-D19)*200*E19," "),IF(D19-F19>0,(D19-F19)*200*E19," ")) | K19: =IF(C19="L",IF(F19-D19<0,F19-D19," "),IF(D19-F19<0,D19-F19," ")) | L19: =IF(C19="L",IF(F19-D19<0,(F19-D19)*200*E19," "),IF(D19-F19<0,(D19-F19)*200*E19," "))
B20: 17 | I20: =IF(C20="L",IF(F20-D20>0,F20-D20," "),IF(D20-F20>0,D20-F20," ")) | J20: =IF(C20="L",IF(F20-D20>0,(F20-D20)*200*E20," "),IF(D20-F20>0,(D20-F20)*200*E20," ")) | K20: =IF(C20="L",IF(F20-D20<0,F20-D20," "),IF(D20-F20<0,D20-F20," ")) | L20: =IF(C20="L",IF(F20-D20<0,(F20-D20)*200*E20," "),IF(D20-F20<0,(D20-F20)*200*E20," "))
B21: 18 | I21: =IF(C21="L",IF(F21-D21>0,F21-D21," "),IF(D21-F21>0,D21-F21," ")) | J21: =IF(C21="L",IF(F21-D21>0,(F21-D21)*200*E21," "),IF(D21-F21>0,(D21-F21)*200*E21," ")) | K21: =IF(C21="L",IF(F21-D21<0,F21-D21," "),IF(D21-F21<0,D21-F21," ")) | L21: =IF(C21="L",IF(F21-D21<0,(F21-D21)*200*E21," "),IF(D21-F21<0,(D21-F21)*200*E21," "))
B22: 19 | I22: =IF(C22="L",IF(F22-D22>0,F22-D22," "),IF(D22-F22>0,D22-F22," ")) | J22: =IF(C22="L",IF(F22-D22>0,(F22-D22)*200*E22," "),IF(D22-F22>0,(D22-F22)*200*E22," ")) | K22: =IF(C22="L",IF(F22-D22<0,F22-D22," "),IF(D22-F22<0,D22-F22," ")) | L22: =IF(C22="L",IF(F22-D22<0,(F22-D22)*200*E22," "),IF(D22-F22<0,(D22-F22)*200*E22," "))
B23: 20 | I23: =IF(C23="L",IF(F23-D23>0,F23-D23," "),IF(D23-F23>0,D23-F23," ")) | J23: =IF(C23="L",IF(F23-D23>0,(F23-D23)*200*E23," "),IF(D23-F23>0,(D23-F23)*200*E23," ")) | K23: =IF(C23="L",IF(F23-D23<0,F23-D23," "),IF(D23-F23<0,D23-F23," ")) | L23: =IF(C23="L",IF(F23-D23<0,(F23-D23)*200*E23," "),IF(D23-F23<0,(D23-F23)*200*E23," "))
B24: 21 | I24: =IF(C24="L",IF(F24-D24>0,F24-D24," "),IF(D24-F24>0,D24-F24," ")) | J24: =IF(C24="L",IF(F24-D24>0,(F24-D24)*200*E24," "),IF(D24-F24>0,(D24-F24)*200*E24," ")) | K24: =IF(C24="L",IF(F24-D24<0,F24-D24," "),IF(D24-F24<0,D24-F24," ")) | L24: =IF(C24="L",IF(F24-D24<0,(F24-D24)*200*E24," "),IF(D24-F24<0,(D24-F24)*200*E24," "))
B25: 22 | I25: =IF(C25="L",IF(F25-D25>0,F25-D25," "),IF(D25-F25>0,D25-F25," ")) | J25: =IF(C25="L",IF(F25-D25>0,(F25-D25)*200*E25," "),IF(D25-F25>0,(D25-F25)*200*E25," ")) | K25: =IF(C25="L",IF(F25-D25<0,F25-D25," "),IF(D25-F25<0,D25-F25," ")) | L25: =IF(C25="L",IF(F25-D25<0,(F25-D25)*200*E25," "),IF(D25-F25<0,(D25-F25)*200*E25," "))
B26: 23 | I26: =IF(C26="L",IF(F26-D26>0,F26-D26," "),IF(D26-F26>0,D26-F26," ")) | J26: =IF(C26="L",IF(F26-D26>0,(F26-D26)*200*E26," "),IF(D26-F26>0,(D26-F26)*200*E26," ")) | K26: =IF(C26="L",IF(F26-D26<0,F26-D26," "),IF(D26-F26<0,D26-F26," ")) | L26: =IF(C26="L",IF(F26-D26<0,(F26-D26)*200*E26," "),IF(D26-F26<0,(D26-F26)*200*E26," "))
B27: 24 | I27: =IF(C27="L",IF(F27-D27>0,F27-D27," "),IF(D27-F27>0,D27-F27," ")) | J27: =IF(C27="L",IF(F27-D27>0,(F27-D27)*200*E27," "),IF(D27-F27>0,(D27-F27)*200*E27," ")) | K27: =IF(C27="L",IF(F27-D27<0,F27-D27," "),IF(D27-F27<0,D27-F27," ")) | L27: =IF(C27="L",IF(F27-D27<0,(F27-D27)*200*E27," "),IF(D27-F27<0,(D27-F27)*200*E27," "))
B28: 25 | I28: =IF(C28="L",IF(F28-D28>0,F28-D28," "),IF(D28-F28>0,D28-F28," ")) | J28: =IF(C28="L",IF(F28-D28>0,(F28-D28)*200*E28," "),IF(D28-F28>0,(D28-F28)*200*E28," ")) | K28: =IF(C28="L",IF(F28-D28<0,F28-D28," "),IF(D28-F28<0,D28-F28," ")) | L28: =IF(C28="L",IF(F28-D28<0,(F28-D28)*200*E28," "),IF(D28-F28<0,(D28-F28)*200*E28," "))
A29: calculate | B29: =COUNT(I4:I28) -> 1 | C29: =COUNT(K4:K28) -> 0 | D29: =SUM(E4:E28)*2 -> 2 | I29: Commission per CON | K29: Com & Vat
I30: 15 | K30: =I30*D29*1.07 -> 32.1
A34: Open | F34: Close | I34: Gain | K34: Loss | O34: Score Board
A35: Date | B35: Order | C35: Side | D35: Price | E35: Volume | F35: Price | I35: จุด | J35: Amount | K35: จุด | L35: Amount | O35: Accuracy & Gain/Loss perform
A36: 45963 | B36: 1 | I36: =IF(C36="L",IF(F36-D36>0,F36-D36," "),IF(D36-F36>0,D36-F36," ")) | J36: =IF(C36="L",IF(F36-D36>0,(F36-D36)*200*E36," "),IF(D36-F36>0,(D36-F36)*200*E36," ")) | K36: =IF(C36="L",IF(F36-D36<0,F36-D36," "),IF(D36-F36<0,D36-F36," ")) | L36: =IF(C36="L",IF(F36-D36<0,(F36-D36)*200*E36," "),IF(D36-F36<0,(D36-F36)*200*E36," ")) | O36: Total Trade | P36: =B61+C61 -> 0
B37: 2 | I37: =IF(C37="L",IF(F37-D37>0,F37-D37," "),IF(D37-F37>0,D37-F37," ")) | J37: =IF(C37="L",IF(F37-D37>0,(F37-D37)*200*E37," "),IF(D37-F37>0,(D37-F37)*200*E37," ")) | L37: =IF(C37="L",IF(F37-D37<0,(F37-D37)*200*E37," "),IF(D37-F37<0,(D37-F37)*200*E37," ")) | O37: Winning Chance | P37: =B61/P36*100 -> #DIV/0! | Q37: Loss Chance | R37: =C61/P36*100 -> #DIV/0!
B38: 3 | I38: =IF(C38="L",IF(F38-D38>0,F38-D38," "),IF(D38-F38>0,D38-F38," ")) | J38: =IF(C38="L",IF(F38-D38>0,(F38-D38)*200*E38," "),IF(D38-F38>0,(D38-F38)*200*E38," ")) | K38: =IF(C37="L",IF(F37-D37<0,F37-D37," "),IF(D37-F37<0,D37-F37," ")) | L38: =IF(C38="L",IF(F38-D38<0,(F38-D38)*200*E38," "),IF(D38-F38<0,(D38-F38)*200*E38," ")) | O38: Average Gain | P38: =SUM(I36:I60)/B61 -> #DIV/0! | Q38: Average Loss | R38: =SUM(K36:K60)/C61 -> #DIV/0!
B39: 4 | I39: =IF(C39="L",IF(F39-D39>0,F39-D39," "),IF(D39-F39>0,D39-F39," ")) | J39: =IF(C39="L",IF(F39-D39>0,(F39-D39)*200*E39," "),IF(D39-F39>0,(D39-F39)*200*E39," ")) | K39: =IF(C39="L",IF(F39-D39<0,F39-D39," "),IF(D39-F39<0,D39-F39," ")) | L39: =IF(C39="L",IF(F39-D39<0,(F39-D39)*200*E39," "),IF(D39-F39<0,(D39-F39)*200*E39," ")) | O39: Total Gain | P39: =SUM(J36:J60) -> 0 | Q39: Total Loss | R39: =SUM(L36:L60) -> 0
B40: 5 | I40: =IF(C40="L",IF(F40-D40>0,F40-D40," "),IF(D40-F40>0,D40-F40," ")) | J40: =IF(C40="L",IF(F40-D40>0,(F40-D40)*200*E40," "),IF(D40-F40>0,(D40-F40)*200*E40," ")) | K40: =IF(C40="L",IF(F40-D40<0,F40-D40," "),IF(D40-F40<0,D40-F40," ")) | L40: =IF(C40="L",IF(F40-D40<0,(F40-D40)*200*E40," "),IF(D40-F40<0,(D40-F40)*200*E40," ")) | O40: Performance
B41: 6 | I41: =IF(C41="L",IF(F41-D41>0,F41-D41," "),IF(D41-F41>0,D41-F41," ")) | J41: =IF(C41="L",IF(F41-D41>0,(F41-D41)*200*E41," "),IF(D41-F41>0,(D41-F41)*200*E41," ")) | K41: =IF(C41="L",IF(F41-D41<0,F41-D41," "),IF(D41-F41<0,D41-F41," ")) | L41: =IF(C41="L",IF(F41-D41<0,(F41-D41)*200*E41," "),IF(D41-F41<0,(D41-F41)*200*E41," ")) | O41: Net Profit | P41: =P39+R39-K62 -> 0 | Q41: Cost rate | R41: =K62/P41 -> #DIV/0!
B42: 7 | I42: =IF(C42="L",IF(F42-D42>0,F42-D42," "),IF(D42-F42>0,D42-F42," ")) | J42: =IF(C42="L",IF(F42-D42>0,(F42-D42)*200*E42," "),IF(D42-F42>0,(D42-F42)*200*E42," ")) | K42: =IF(C42="L",IF(F42-D42<0,F42-D42," "),IF(D42-F42<0,D42-F42," ")) | L42: =IF(C42="L",IF(F42-D42<0,(F42-D42)*200*E42," "),IF(D42-F42<0,(D42-F42)*200*E42," "))
B43: 8 | I43: =IF(C43="L",IF(F43-D43>0,F43-D43," "),IF(D43-F43>0,D43-F43," ")) | J43: =IF(C43="L",IF(F43-D43>0,(F43-D43)*200*E43," "),IF(D43-F43>0,(D43-F43)*200*E43," ")) | K43: =IF(C43="L",IF(F43-D43<0,F43-D43," "),IF(D43-F43<0,D43-F43," ")) | L43: =IF(C43="L",IF(F43-D43<0,(F43-D43)*200*E43," "),IF(D43-F43<0,(D43-F43)*200*E43," ")) | O43: Expected Return | R43: =IF(R39<0,((P37*P38/100)+(R37*R38/100)),P38) -> #DIV/0!
...

Sheet Graph
A1: port | B1: win%
A2: =Record!K1+Record!P9 -> 18067.9 | B2: =Record!P5 -> 100
A3: =A2+Record!P41 -> 18067.9 | B3: =Record!P37 -> #DIV/0!
A4: =A3+Record!P73 -> 18067.9 | B4: =Record!P69 -> #DIV/0!
A5: =A4+Record!P105 -> 18067.9 | B5: =Record!P101 -> #DIV/0!
A6: =A5+Record!P137 -> 18067.9 | B6: =Record!P133 -> #DIV/0!
A7: =A6+Record!P169 -> 18067.9 | B7: =Record!P165 -> #DIV/0!
A8: =A7+Record!P201 -> 18067.9 | B8: =Record!P197 -> #DIV/0!
A9: =A8+Record!P233 -> 18067.9 | B9: =Record!P229 -> #DIV/0!
A10: =A9+Record!P265 -> 18067.9 | B10: =Record!P261 -> #DIV/0!
A11: =A10+Record!P297 -> 18067.9 | B11: =Record!P293 -> #DIV/0!
A12: =A11+Record!P329 -> 18067.9 | B12: =Record!P325 -> #DIV/0!
A13: =A12+Record!P361 -> 18067.9 | B13: =Record!P357 -> #DIV/0!
A14: =A13+Record!P393 -> 18067.9 | B14: =Record!P389 -> #DIV/0!
A15: =A14+Record!P425 -> 18067.9 | B15: =Record!P421 -> #DIV/0!
A16: =A15+Record!P457 -> 18067.9 | B16: =Record!P453 -> #DIV/0!
A17: =A16+Record!P489 -> 18067.9 | B17: =Record!P485 -> #DIV/0!
A18: =A17+Record!P521 -> 18067.9 | B18: =Record!P517 -> #DIV/0!
A19: =A18+Record!P553 -> 18067.9 | B19: =Record!P549 -> #DIV/0!
A20: =A19+Record!P585 -> 18067.9 | B20: =Record!P581 -> #DIV/0!
A21: =A20+Record!P617 -> 18067.9 | B21: =Record!P613 -> #DIV/0!
A22: =A21+Record!P649 -> 18067.9 | B22: =Record!P645 -> #DIV/0!
A23: =A22+Record!P681 -> 18067.9 | B23: =Record!P677 -> #DIV/0!
A24: =A23+Record!P713 -> 18067.9 | B24: =Record!P709 -> #DIV/0!
A25: =A24+Record!P745 -> 18067.9 | B25: =Record!P741 -> #DIV/0!
A26: =A25+Record!P777 -> 18067.9 | B26: =Record!P773 -> #DIV/0!
A27: =A26+Record!P809 -> 18067.9 | B27: =Record!P805 -> #DIV/0!
A29: ex r | B29: avg gain
A30: =Record!R11 -> 0 | B30: =Record!P6 -> 0
A31: =Record!R43 -> #DIV/0! | B31: =Record!P38 -> #DIV/0!
A32: =Record!R75 -> #DIV/0! | B32: =Record!P70 -> #DIV/0!
A33: =Record!R107 -> #DIV/0! | B33: =Record!P102 -> #DIV/0!
A34: =Record!R139 -> #DIV/0! | B34: =Record!P134 -> #DIV/0!
A35: =Record!R171 -> #DIV/0! | B35: =Record!P166 -> #DIV/0!
A36: =Record!R203 -> #DIV/0! | B36: =Record!P198 -> #DIV/0!
A37: =Record!R235 -> #DIV/0! | B37: =Record!P230 -> #DIV/0!
A38: =Record!R267 -> #DIV/0! | B38: =Record!P262 -> #DIV/0!
A39: =Record!R299 -> #DIV/0! | B39: =Record!P294 -> #DIV/0!
A40: =Record!R331 -> #DIV/0! | B40: =Record!P326 -> #DIV/0!
A41: =Record!R363 -> #DIV/0! | B41: =Record!P358 -> #DIV/0!
...

Sheet Sheet3
